 * Serving Flask app './ontobot/__init__.py'
 * Debug mode: on
WARNING: This is a development server. Do not use it in a production deployment. Use a production WSGI server instead.
 * Running on all addresses (0.0.0.0)
 * Running on http://127.0.0.1:5000
 * Running on http://192.168.1.2:5000
Press CTRL+C to quit
 * Restarting with stat
 * Debugger is active!
 * Debugger PIN: 128-222-380
127.0.0.1 - - [14/Mar/2023 18:34:46] "POST /op/checkpoint_1/taxowl_generate HTTP/1.1" 200 -
127.0.0.1 - - [14/Mar/2023 18:35:18] "POST /onto/checkpoint_1/validate HTTP/1.1" 200 -
127.0.0.1 - - [14/Mar/2023 18:37:33] "POST /onto/checkpoint_1/validate HTTP/1.1" 200 -
127.0.0.1 - - [14/Mar/2023 18:37:47] "POST /op/checkpoint_1/taxowl_generate HTTP/1.1" 200 -
127.0.0.1 - - [14/Mar/2023 18:38:39] "POST /op/checkpoint_1/op_generate HTTP/1.1" 200 -
127.0.0.1 - - [14/Mar/2023 19:19:09] "POST /onto/checkpoint_1/validate HTTP/1.1" 200 -
127.0.0.1 - - [14/Mar/2023 19:19:31] "POST /onto/checkpoint_1/validate HTTP/1.1" 200 -
127.0.0.1 - - [14/Mar/2023 19:19:55] "POST /onto/checkpoint_1/validate HTTP/1.1" 200 -
127.0.0.1 - - [14/Mar/2023 19:21:18] "POST /onto/checkpoint_1/validate HTTP/1.1" 200 -
 * Detected change in 'C:\\GitHub\\Ontobot\\ontobot-app\\flask-server\\ontobot\\services\\populate_service.py', reloading
 * Restarting with stat
 * Debugger is active!
 * Debugger PIN: 128-222-380
 * Detected change in 'C:\\GitHub\\Ontobot\\ontobot-app\\flask-server\\ontobot\\services\\populate_service.py', reloading
 * Restarting with stat
Traceback (most recent call last):
  File "C:\Users\Asus\.virtualenvs\flask-server-AxbIE3V_\lib\site-packages\flask\cli.py", line 897, in run_command
    app = info.load_app()
  File "C:\Users\Asus\.virtualenvs\flask-server-AxbIE3V_\lib\site-packages\flask\cli.py", line 308, in load_app
    app = locate_app(import_name, name)
  File "C:\Users\Asus\.virtualenvs\flask-server-AxbIE3V_\lib\site-packages\flask\cli.py", line 218, in locate_app
    __import__(module_name)
  File "C:\GitHub\Ontobot\ontobot-app\flask-server\ontobot\__init__.py", line 3, in <module>
    from ontobot.services import taxonomy_service, op_service, populate_service
  File "C:\GitHub\Ontobot\ontobot-app\flask-server\ontobot\services\populate_service.py", line 101
    worksheet.write(0, col, col_name, bold)
IndentationError: unexpected indent
 * Debugger is active!
 * Debugger PIN: 117-486-287
 * Detected change in 'C:\\GitHub\\Ontobot\\ontobot-app\\flask-server\\ontobot\\services\\populate_service.py', reloading
 * Restarting with stat
 * Debugger is active!
 * Debugger PIN: 128-222-380
 * Detected change in 'C:\\GitHub\\Ontobot\\ontobot-app\\flask-server\\ontobot\\services\\populate_service.py', reloading
 * Restarting with stat
 * Debugger is active!
 * Debugger PIN: 128-222-380
 * Detected change in 'C:\\GitHub\\Ontobot\\ontobot-app\\flask-server\\ontobot\\services\\populate_service.py', reloading
 * Restarting with stat
 * Debugger is active!
 * Debugger PIN: 128-222-380
 * Detected change in 'C:\\GitHub\\Ontobot\\ontobot-app\\flask-server\\ontobot\\services\\populate_service.py', reloading
 * Restarting with stat
 * Debugger is active!
 * Debugger PIN: 128-222-380
 * Detected change in 'C:\\GitHub\\Ontobot\\ontobot-app\\flask-server\\ontobot\\services\\populate_service.py', reloading
 * Restarting with stat
 * Debugger is active!
 * Debugger PIN: 128-222-380
 * Detected change in 'C:\\GitHub\\Ontobot\\ontobot-app\\flask-server\\ontobot\\services\\populate_service.py', reloading
 * Restarting with stat
 * Debugger is active!
 * Debugger PIN: 128-222-380
 * Detected change in 'C:\\GitHub\\Ontobot\\ontobot-app\\flask-server\\ontobot\\services\\populate_service.py', reloading
 * Restarting with stat
 * Debugger is active!
 * Debugger PIN: 128-222-380
 * Detected change in 'C:\\GitHub\\Ontobot\\ontobot-app\\flask-server\\ontobot\\services\\populate_service.py', reloading
 * Restarting with stat
 * Debugger is active!
 * Debugger PIN: 128-222-380
 * Detected change in 'C:\\GitHub\\Ontobot\\ontobot-app\\flask-server\\ontobot\\services\\populate_service.py', reloading
 * Restarting with stat
 * Debugger is active!
 * Debugger PIN: 128-222-380
127.0.0.1 - - [14/Mar/2023 21:08:01] "POST /op/checkpoint_1/populate HTTP/1.1" 200 -
127.0.0.1 - - [14/Mar/2023 21:08:11] "POST /op/checkpoint_1/populate HTTP/1.1" 200 -
 * Detected change in 'C:\\GitHub\\Ontobot\\ontobot-app\\flask-server\\ontobot\\services\\populate_service.py', reloading
 * Restarting with stat
 * Debugger is active!
 * Debugger PIN: 128-222-380
 * Detected change in 'C:\\GitHub\\Ontobot\\ontobot-app\\flask-server\\ontobot\\services\\populate_service.py', reloading
 * Restarting with stat
Traceback (most recent call last):
  File "C:\Users\Asus\.virtualenvs\flask-server-AxbIE3V_\lib\site-packages\flask\cli.py", line 897, in run_command
    app = info.load_app()
  File "C:\Users\Asus\.virtualenvs\flask-server-AxbIE3V_\lib\site-packages\flask\cli.py", line 308, in load_app
    app = locate_app(import_name, name)
  File "C:\Users\Asus\.virtualenvs\flask-server-AxbIE3V_\lib\site-packages\flask\cli.py", line 218, in locate_app
    __import__(module_name)
  File "C:\GitHub\Ontobot\ontobot-app\flask-server\ontobot\__init__.py", line 3, in <module>
    from ontobot.services import taxonomy_service, op_service, populate_service
  File "C:\GitHub\Ontobot\ontobot-app\flask-server\ontobot\services\populate_service.py", line 68
    def 
        ^
SyntaxError: invalid syntax
 * Debugger is active!
 * Debugger PIN: 117-486-287
 * Detected change in 'C:\\GitHub\\Ontobot\\ontobot-app\\flask-server\\ontobot\\services\\populate_service.py', reloading
 * Restarting with stat
Traceback (most recent call last):
  File "C:\Users\Asus\.virtualenvs\flask-server-AxbIE3V_\lib\site-packages\flask\cli.py", line 897, in run_command
    app = info.load_app()
  File "C:\Users\Asus\.virtualenvs\flask-server-AxbIE3V_\lib\site-packages\flask\cli.py", line 308, in load_app
    app = locate_app(import_name, name)
  File "C:\Users\Asus\.virtualenvs\flask-server-AxbIE3V_\lib\site-packages\flask\cli.py", line 218, in locate_app
    __import__(module_name)
  File "C:\GitHub\Ontobot\ontobot-app\flask-server\ontobot\__init__.py", line 3, in <module>
    from ontobot.services import taxonomy_service, op_service, populate_service
  File "C:\GitHub\Ontobot\ontobot-app\flask-server\ontobot\services\populate_service.py", line 68
    def convert_excel
                     ^
SyntaxError: invalid syntax
 * Debugger is active!
 * Debugger PIN: 117-486-287
 * Detected change in 'C:\\GitHub\\Ontobot\\ontobot-app\\flask-server\\ontobot\\services\\populate_service.py', reloading
 * Restarting with stat
Traceback (most recent call last):
  File "C:\Users\Asus\.virtualenvs\flask-server-AxbIE3V_\lib\site-packages\flask\cli.py", line 897, in run_command
    app = info.load_app()
  File "C:\Users\Asus\.virtualenvs\flask-server-AxbIE3V_\lib\site-packages\flask\cli.py", line 308, in load_app
    app = locate_app(import_name, name)
  File "C:\Users\Asus\.virtualenvs\flask-server-AxbIE3V_\lib\site-packages\flask\cli.py", line 218, in locate_app
    __import__(module_name)
  File "C:\GitHub\Ontobot\ontobot-app\flask-server\ontobot\__init__.py", line 3, in <module>
    from ontobot.services import taxonomy_service, op_service, populate_service
  File "C:\GitHub\Ontobot\ontobot-app\flask-server\ontobot\services\populate_service.py", line 68
    def convert_excel_file
                          ^
SyntaxError: invalid syntax
 * Debugger is active!
 * Debugger PIN: 117-486-287
 * Detected change in 'C:\\GitHub\\Ontobot\\ontobot-app\\flask-server\\ontobot\\services\\populate_service.py', reloading
 * Restarting with stat
Traceback (most recent call last):
  File "C:\Users\Asus\.virtualenvs\flask-server-AxbIE3V_\lib\site-packages\flask\cli.py", line 897, in run_command
    app = info.load_app()
  File "C:\Users\Asus\.virtualenvs\flask-server-AxbIE3V_\lib\site-packages\flask\cli.py", line 308, in load_app
    app = locate_app(import_name, name)
  File "C:\Users\Asus\.virtualenvs\flask-server-AxbIE3V_\lib\site-packages\flask\cli.py", line 218, in locate_app
    __import__(module_name)
  File "C:\GitHub\Ontobot\ontobot-app\flask-server\ontobot\__init__.py", line 3, in <module>
    from ontobot.services import taxonomy_service, op_service, populate_service
  File "C:\GitHub\Ontobot\ontobot-app\flask-server\ontobot\services\populate_service.py", line 68
    def convert_excel_file()
                            ^
SyntaxError: expected ':'
 * Debugger is active!
 * Debugger PIN: 117-486-287
 * Detected change in 'C:\\GitHub\\Ontobot\\ontobot-app\\flask-server\\ontobot\\services\\populate_service.py', reloading
 * Restarting with stat
 * Debugger is active!
 * Debugger PIN: 128-222-380
 * Detected change in 'C:\\GitHub\\Ontobot\\ontobot-app\\flask-server\\ontobot\\services\\populate_service.py', reloading
 * Restarting with stat
 * Debugger is active!
 * Debugger PIN: 128-222-380
 * Detected change in 'C:\\GitHub\\Ontobot\\ontobot-app\\flask-server\\ontobot\\services\\populate_service.py', reloading
 * Restarting with stat
Traceback (most recent call last):
  File "C:\Users\Asus\.virtualenvs\flask-server-AxbIE3V_\lib\site-packages\flask\cli.py", line 897, in run_command
    app = info.load_app()
  File "C:\Users\Asus\.virtualenvs\flask-server-AxbIE3V_\lib\site-packages\flask\cli.py", line 308, in load_app
    app = locate_app(import_name, name)
  File "C:\Users\Asus\.virtualenvs\flask-server-AxbIE3V_\lib\site-packages\flask\cli.py", line 223, in locate_app
    raise NoAppException(
flask.cli.NoAppException: While importing 'ontobot', an ImportError was raised:

Traceback (most recent call last):
  File "C:\Users\Asus\.virtualenvs\flask-server-AxbIE3V_\lib\site-packages\flask\cli.py", line 218, in locate_app
    __import__(module_name)
  File "C:\GitHub\Ontobot\ontobot-app\flask-server\ontobot\__init__.py", line 3, in <module>
    from ontobot.services import taxonomy_service, op_service, populate_service
  File "C:\GitHub\Ontobot\ontobot-app\flask-server\ontobot\services\populate_service.py", line 2, in <module>
    import pa
ModuleNotFoundError: No module named 'pa'

 * Debugger is active!
 * Debugger PIN: 117-486-287
 * Detected change in 'C:\\GitHub\\Ontobot\\ontobot-app\\flask-server\\ontobot\\services\\populate_service.py', reloading
 * Restarting with stat
Traceback (most recent call last):
  File "C:\Users\Asus\.virtualenvs\flask-server-AxbIE3V_\lib\site-packages\flask\cli.py", line 897, in run_command
    app = info.load_app()
  File "C:\Users\Asus\.virtualenvs\flask-server-AxbIE3V_\lib\site-packages\flask\cli.py", line 308, in load_app
    app = locate_app(import_name, name)
  File "C:\Users\Asus\.virtualenvs\flask-server-AxbIE3V_\lib\site-packages\flask\cli.py", line 223, in locate_app
    raise NoAppException(
flask.cli.NoAppException: While importing 'ontobot', an ImportError was raised:

Traceback (most recent call last):
  File "C:\Users\Asus\.virtualenvs\flask-server-AxbIE3V_\lib\site-packages\flask\cli.py", line 218, in locate_app
    __import__(module_name)
  File "C:\GitHub\Ontobot\ontobot-app\flask-server\ontobot\__init__.py", line 3, in <module>
    from ontobot.services import taxonomy_service, op_service, populate_service
  File "C:\GitHub\Ontobot\ontobot-app\flask-server\ontobot\services\populate_service.py", line 2, in <module>
    import pandas as pd
ModuleNotFoundError: No module named 'pandas'

 * Debugger is active!
 * Debugger PIN: 117-486-287
 * Detected change in 'C:\\GitHub\\Ontobot\\ontobot-app\\flask-server\\ontobot\\services\\populate_service.py', reloading
 * Restarting with stat
Traceback (most recent call last):
  File "C:\Users\Asus\.virtualenvs\flask-server-AxbIE3V_\lib\site-packages\flask\cli.py", line 897, in run_command
    app = info.load_app()
  File "C:\Users\Asus\.virtualenvs\flask-server-AxbIE3V_\lib\site-packages\flask\cli.py", line 308, in load_app
    app = locate_app(import_name, name)
  File "C:\Users\Asus\.virtualenvs\flask-server-AxbIE3V_\lib\site-packages\flask\cli.py", line 218, in locate_app
    __import__(module_name)
  File "C:\GitHub\Ontobot\ontobot-app\flask-server\ontobot\__init__.py", line 3, in <module>
    from ontobot.services import taxonomy_service, op_service, populate_service
  File "C:\GitHub\Ontobot\ontobot-app\flask-server\ontobot\services\populate_service.py", line 71
    df = pd.read_excel('example.xlsx', sheet_name=None)
    ^^
IndentationError: expected an indented block after function definition on line 69
 * Debugger is active!
 * Debugger PIN: 117-486-287
 * Detected change in 'C:\\GitHub\\Ontobot\\ontobot-app\\flask-server\\ontobot\\services\\populate_service.py', reloading
 * Restarting with stat
Traceback (most recent call last):
  File "C:\Users\Asus\.virtualenvs\flask-server-AxbIE3V_\lib\site-packages\flask\cli.py", line 897, in run_command
    app = info.load_app()
  File "C:\Users\Asus\.virtualenvs\flask-server-AxbIE3V_\lib\site-packages\flask\cli.py", line 308, in load_app
    app = locate_app(import_name, name)
  File "C:\Users\Asus\.virtualenvs\flask-server-AxbIE3V_\lib\site-packages\flask\cli.py", line 223, in locate_app
    raise NoAppException(
flask.cli.NoAppException: While importing 'ontobot', an ImportError was raised:

Traceback (most recent call last):
  File "C:\Users\Asus\.virtualenvs\flask-server-AxbIE3V_\lib\site-packages\flask\cli.py", line 218, in locate_app
    __import__(module_name)
  File "C:\GitHub\Ontobot\ontobot-app\flask-server\ontobot\__init__.py", line 3, in <module>
    from ontobot.services import taxonomy_service, op_service, populate_service
  File "C:\GitHub\Ontobot\ontobot-app\flask-server\ontobot\services\populate_service.py", line 2, in <module>
    import pandas as pd
ModuleNotFoundError: No module named 'pandas'

 * Debugger is active!
 * Debugger PIN: 117-486-287
 * Detected change in 'C:\\GitHub\\Ontobot\\ontobot-app\\flask-server\\ontobot\\services\\populate_service.py', reloading
 * Restarting with stat
Traceback (most recent call last):
  File "C:\Users\Asus\.virtualenvs\flask-server-AxbIE3V_\lib\site-packages\flask\cli.py", line 897, in run_command
    app = info.load_app()
  File "C:\Users\Asus\.virtualenvs\flask-server-AxbIE3V_\lib\site-packages\flask\cli.py", line 308, in load_app
    app = locate_app(import_name, name)
  File "C:\Users\Asus\.virtualenvs\flask-server-AxbIE3V_\lib\site-packages\flask\cli.py", line 223, in locate_app
    raise NoAppException(
flask.cli.NoAppException: While importing 'ontobot', an ImportError was raised:

Traceback (most recent call last):
  File "C:\Users\Asus\.virtualenvs\flask-server-AxbIE3V_\lib\site-packages\flask\cli.py", line 218, in locate_app
    __import__(module_name)
  File "C:\GitHub\Ontobot\ontobot-app\flask-server\ontobot\__init__.py", line 3, in <module>
    from ontobot.services import taxonomy_service, op_service, populate_service
  File "C:\GitHub\Ontobot\ontobot-app\flask-server\ontobot\services\populate_service.py", line 2, in <module>
    import pandas as pd
ModuleNotFoundError: No module named 'pandas'

 * Debugger is active!
 * Debugger PIN: 117-486-287
127.0.0.1 - - [14/Mar/2023 21:53:39] "POST /op/checkpoint_1/populate HTTP/1.1" 500 -
Traceback (most recent call last):
  File "C:\Users\Asus\.virtualenvs\flask-server-AxbIE3V_\lib\site-packages\flask\cli.py", line 906, in app
    raise err from None
  File "C:\Users\Asus\.virtualenvs\flask-server-AxbIE3V_\lib\site-packages\flask\cli.py", line 897, in run_command
    app = info.load_app()
  File "C:\Users\Asus\.virtualenvs\flask-server-AxbIE3V_\lib\site-packages\flask\cli.py", line 308, in load_app
    app = locate_app(import_name, name)
  File "C:\Users\Asus\.virtualenvs\flask-server-AxbIE3V_\lib\site-packages\flask\cli.py", line 223, in locate_app
    raise NoAppException(
flask.cli.NoAppException: While importing 'ontobot', an ImportError was raised:

Traceback (most recent call last):
  File "C:\Users\Asus\.virtualenvs\flask-server-AxbIE3V_\lib\site-packages\flask\cli.py", line 218, in locate_app
    __import__(module_name)
  File "C:\GitHub\Ontobot\ontobot-app\flask-server\ontobot\__init__.py", line 3, in <module>
    from ontobot.services import taxonomy_service, op_service, populate_service
  File "C:\GitHub\Ontobot\ontobot-app\flask-server\ontobot\services\populate_service.py", line 2, in <module>
    import pandas as pd
ModuleNotFoundError: No module named 'pandas'

 * Detected change in 'C:\\GitHub\\Ontobot\\ontobot-app\\flask-server\\ontobot\\services\\populate_service.py', reloading
 * Restarting with stat
Traceback (most recent call last):
  File "C:\Users\Asus\.virtualenvs\flask-server-AxbIE3V_\lib\site-packages\flask\cli.py", line 897, in run_command
    app = info.load_app()
  File "C:\Users\Asus\.virtualenvs\flask-server-AxbIE3V_\lib\site-packages\flask\cli.py", line 308, in load_app
    app = locate_app(import_name, name)
  File "C:\Users\Asus\.virtualenvs\flask-server-AxbIE3V_\lib\site-packages\flask\cli.py", line 223, in locate_app
    raise NoAppException(
flask.cli.NoAppException: While importing 'ontobot', an ImportError was raised:

Traceback (most recent call last):
  File "C:\Users\Asus\.virtualenvs\flask-server-AxbIE3V_\lib\site-packages\flask\cli.py", line 218, in locate_app
    __import__(module_name)
  File "C:\GitHub\Ontobot\ontobot-app\flask-server\ontobot\__init__.py", line 3, in <module>
    from ontobot.services import taxonomy_service, op_service, populate_service
  File "C:\GitHub\Ontobot\ontobot-app\flask-server\ontobot\services\populate_service.py", line 2, in <module>
    import pandas as pd
ModuleNotFoundError: No module named 'pandas'

 * Debugger is active!
 * Debugger PIN: 117-486-287
 * Detected change in 'C:\\GitHub\\Ontobot\\ontobot-app\\flask-server\\ontobot\\services\\populate_service.py', reloading
 * Restarting with stat
 * Debugger is active!
 * Debugger PIN: 128-222-380
127.0.0.1 - - [14/Mar/2023 21:54:12] "POST /op/checkpoint_1/populate HTTP/1.1" 200 -
127.0.0.1 - - [14/Mar/2023 21:54:29] "POST /op/checkpoint_1/populate HTTP/1.1" 200 -
 * Detected change in 'C:\\Users\\Asus\\.virtualenvs\\flask-server-AxbIE3V_\\lib\\site-packages\\xlsxwriter\\packager.py', reloading
 * Restarting with stat
 * Debugger is active!
 * Debugger PIN: 128-222-380
 * Detected change in 'C:\\GitHub\\Ontobot\\ontobot-app\\flask-server\\ontobot\\services\\populate_service.py', reloading
 * Restarting with stat
 * Debugger is active!
 * Debugger PIN: 128-222-380
 * Detected change in 'C:\\GitHub\\Ontobot\\ontobot-app\\flask-server\\ontobot\\services\\populate_service.py', reloading
 * Restarting with stat
 * Debugger is active!
 * Debugger PIN: 128-222-380
 * Detected change in 'C:\\GitHub\\Ontobot\\ontobot-app\\flask-server\\ontobot\\services\\populate_service.py', reloading
 * Restarting with stat
 * Debugger is active!
 * Debugger PIN: 128-222-380
 * Detected change in 'C:\\GitHub\\Ontobot\\ontobot-app\\flask-server\\ontobot\\services\\populate_service.py', reloading
 * Restarting with stat
 * Debugger is active!
 * Debugger PIN: 128-222-380
 * Detected change in 'C:\\GitHub\\Ontobot\\ontobot-app\\flask-server\\ontobot\\services\\populate_service.py', reloading
 * Restarting with stat
 * Debugger is active!
 * Debugger PIN: 128-222-380
 * Detected change in 'C:\\GitHub\\Ontobot\\ontobot-app\\flask-server\\ontobot\\services\\populate_service.py', reloading
 * Restarting with stat
 * Debugger is active!
 * Debugger PIN: 128-222-380
 * Detected change in 'C:\\GitHub\\Ontobot\\ontobot-app\\flask-server\\ontobot\\services\\populate_service.py', reloading
 * Restarting with stat
 * Debugger is active!
 * Debugger PIN: 128-222-380
 * Detected change in 'C:\\GitHub\\Ontobot\\ontobot-app\\flask-server\\ontobot\\services\\populate_service.py', reloading
 * Restarting with stat
 * Debugger is active!
 * Debugger PIN: 128-222-380
 * Detected change in 'C:\\GitHub\\Ontobot\\ontobot-app\\flask-server\\ontobot\\services\\populate_service.py', reloading
 * Restarting with stat
 * Debugger is active!
 * Debugger PIN: 128-222-380
 * Detected change in 'C:\\GitHub\\Ontobot\\ontobot-app\\flask-server\\ontobot\\services\\populate_service.py', reloading
 * Restarting with stat
 * Debugger is active!
 * Debugger PIN: 128-222-380
 * Detected change in 'C:\\GitHub\\Ontobot\\ontobot-app\\flask-server\\ontobot\\services\\populate_service.py', reloading
 * Restarting with stat
 * Debugger is active!
 * Debugger PIN: 128-222-380
 * Detected change in 'C:\\GitHub\\Ontobot\\ontobot-app\\flask-server\\ontobot\\__init__.py', reloading
 * Restarting with stat
Traceback (most recent call last):
  File "C:\Users\Asus\.virtualenvs\flask-server-AxbIE3V_\lib\site-packages\flask\cli.py", line 897, in run_command
    app = info.load_app()
  File "C:\Users\Asus\.virtualenvs\flask-server-AxbIE3V_\lib\site-packages\flask\cli.py", line 308, in load_app
    app = locate_app(import_name, name)
  File "C:\Users\Asus\.virtualenvs\flask-server-AxbIE3V_\lib\site-packages\flask\cli.py", line 218, in locate_app
    __import__(module_name)
  File "C:\GitHub\Ontobot\ontobot-app\flask-server\ontobot\__init__.py", line 37, in <module>
    def get_populate():
  File "C:\Users\Asus\.virtualenvs\flask-server-AxbIE3V_\lib\site-packages\flask\scaffold.py", line 449, in decorator
    self.add_url_rule(rule, endpoint, f, **options)
  File "C:\Users\Asus\.virtualenvs\flask-server-AxbIE3V_\lib\site-packages\flask\scaffold.py", line 50, in wrapper_func
    return f(self, *args, **kwargs)
  File "C:\Users\Asus\.virtualenvs\flask-server-AxbIE3V_\lib\site-packages\flask\app.py", line 1361, in add_url_rule
    raise AssertionError(
AssertionError: View function mapping is overwriting an existing endpoint function: get_populate
 * Debugger is active!
 * Debugger PIN: 117-486-287
 * Detected change in 'C:\\GitHub\\Ontobot\\ontobot-app\\flask-server\\ontobot\\__init__.py', reloading
 * Restarting with stat
Traceback (most recent call last):
  File "C:\Users\Asus\.virtualenvs\flask-server-AxbIE3V_\lib\site-packages\flask\cli.py", line 897, in run_command
    app = info.load_app()
  File "C:\Users\Asus\.virtualenvs\flask-server-AxbIE3V_\lib\site-packages\flask\cli.py", line 308, in load_app
    app = locate_app(import_name, name)
  File "C:\Users\Asus\.virtualenvs\flask-server-AxbIE3V_\lib\site-packages\flask\cli.py", line 218, in locate_app
    __import__(module_name)
  File "C:\GitHub\Ontobot\ontobot-app\flask-server\ontobot\__init__.py", line 37, in <module>
    def get_populate():
  File "C:\Users\Asus\.virtualenvs\flask-server-AxbIE3V_\lib\site-packages\flask\scaffold.py", line 449, in decorator
    self.add_url_rule(rule, endpoint, f, **options)
  File "C:\Users\Asus\.virtualenvs\flask-server-AxbIE3V_\lib\site-packages\flask\scaffold.py", line 50, in wrapper_func
    return f(self, *args, **kwargs)
  File "C:\Users\Asus\.virtualenvs\flask-server-AxbIE3V_\lib\site-packages\flask\app.py", line 1361, in add_url_rule
    raise AssertionError(
AssertionError: View function mapping is overwriting an existing endpoint function: get_populate
 * Debugger is active!
 * Debugger PIN: 117-486-287
 * Detected change in 'C:\\GitHub\\Ontobot\\ontobot-app\\flask-server\\ontobot\\__init__.py', reloading
 * Restarting with stat
Traceback (most recent call last):
  File "C:\Users\Asus\.virtualenvs\flask-server-AxbIE3V_\lib\site-packages\flask\cli.py", line 897, in run_command
    app = info.load_app()
  File "C:\Users\Asus\.virtualenvs\flask-server-AxbIE3V_\lib\site-packages\flask\cli.py", line 308, in load_app
    app = locate_app(import_name, name)
  File "C:\Users\Asus\.virtualenvs\flask-server-AxbIE3V_\lib\site-packages\flask\cli.py", line 218, in locate_app
    __import__(module_name)
  File "C:\GitHub\Ontobot\ontobot-app\flask-server\ontobot\__init__.py", line 37, in <module>
    def get_populate():
  File "C:\Users\Asus\.virtualenvs\flask-server-AxbIE3V_\lib\site-packages\flask\scaffold.py", line 449, in decorator
    self.add_url_rule(rule, endpoint, f, **options)
  File "C:\Users\Asus\.virtualenvs\flask-server-AxbIE3V_\lib\site-packages\flask\scaffold.py", line 50, in wrapper_func
    return f(self, *args, **kwargs)
  File "C:\Users\Asus\.virtualenvs\flask-server-AxbIE3V_\lib\site-packages\flask\app.py", line 1361, in add_url_rule
    raise AssertionError(
AssertionError: View function mapping is overwriting an existing endpoint function: get_populate
 * Debugger is active!
 * Debugger PIN: 117-486-287
 * Detected change in 'C:\\GitHub\\Ontobot\\ontobot-app\\flask-server\\ontobot\\__init__.py', reloading
 * Restarting with stat
Traceback (most recent call last):
  File "C:\Users\Asus\.virtualenvs\flask-server-AxbIE3V_\lib\site-packages\flask\cli.py", line 897, in run_command
    app = info.load_app()
  File "C:\Users\Asus\.virtualenvs\flask-server-AxbIE3V_\lib\site-packages\flask\cli.py", line 308, in load_app
    app = locate_app(import_name, name)
  File "C:\Users\Asus\.virtualenvs\flask-server-AxbIE3V_\lib\site-packages\flask\cli.py", line 218, in locate_app
    __import__(module_name)
  File "C:\GitHub\Ontobot\ontobot-app\flask-server\ontobot\__init__.py", line 37, in <module>
    def get_populate():
  File "C:\Users\Asus\.virtualenvs\flask-server-AxbIE3V_\lib\site-packages\flask\scaffold.py", line 449, in decorator
    self.add_url_rule(rule, endpoint, f, **options)
  File "C:\Users\Asus\.virtualenvs\flask-server-AxbIE3V_\lib\site-packages\flask\scaffold.py", line 50, in wrapper_func
    return f(self, *args, **kwargs)
  File "C:\Users\Asus\.virtualenvs\flask-server-AxbIE3V_\lib\site-packages\flask\app.py", line 1361, in add_url_rule
    raise AssertionError(
AssertionError: View function mapping is overwriting an existing endpoint function: get_populate
 * Debugger is active!
 * Debugger PIN: 117-486-287
 * Detected change in 'C:\\GitHub\\Ontobot\\ontobot-app\\flask-server\\ontobot\\__init__.py', reloading
 * Restarting with stat
 * Debugger is active!
 * Debugger PIN: 128-222-380
 * Detected change in 'C:\\GitHub\\Ontobot\\ontobot-app\\flask-server\\ontobot\\services\\populate_service.py', reloading
 * Restarting with stat
 * Debugger is active!
 * Debugger PIN: 128-222-380
 * Detected change in 'C:\\GitHub\\Ontobot\\ontobot-app\\flask-server\\ontobot\\services\\populate_service.py', reloading
 * Restarting with stat
Traceback (most recent call last):
  File "C:\Users\Asus\.virtualenvs\flask-server-AxbIE3V_\lib\site-packages\flask\cli.py", line 897, in run_command
    app = info.load_app()
  File "C:\Users\Asus\.virtualenvs\flask-server-AxbIE3V_\lib\site-packages\flask\cli.py", line 308, in load_app
    app = locate_app(import_name, name)
  File "C:\Users\Asus\.virtualenvs\flask-server-AxbIE3V_\lib\site-packages\flask\cli.py", line 218, in locate_app
    __import__(module_name)
  File "C:\GitHub\Ontobot\ontobot-app\flask-server\ontobot\__init__.py", line 3, in <module>
    from ontobot.services import taxonomy_service, op_service, populate_service
  File "C:\GitHub\Ontobot\ontobot-app\flask-server\ontobot\services\populate_service.py", line 93
    return Response.
                    ^
SyntaxError: invalid syntax
 * Debugger is active!
 * Debugger PIN: 117-486-287
 * Detected change in 'C:\\GitHub\\Ontobot\\ontobot-app\\flask-server\\ontobot\\services\\populate_service.py', reloading
 * Restarting with stat
 * Debugger is active!
 * Debugger PIN: 128-222-380
 * Detected change in 'C:\\GitHub\\Ontobot\\ontobot-app\\flask-server\\ontobot\\services\\populate_service.py', reloading
 * Restarting with stat
 * Debugger is active!
 * Debugger PIN: 128-222-380
 * Detected change in 'C:\\GitHub\\Ontobot\\ontobot-app\\flask-server\\ontobot\\services\\populate_service.py', reloading
 * Restarting with stat
Traceback (most recent call last):
  File "C:\Users\Asus\.virtualenvs\flask-server-AxbIE3V_\lib\site-packages\flask\cli.py", line 897, in run_command
    app = info.load_app()
  File "C:\Users\Asus\.virtualenvs\flask-server-AxbIE3V_\lib\site-packages\flask\cli.py", line 308, in load_app
    app = locate_app(import_name, name)
  File "C:\Users\Asus\.virtualenvs\flask-server-AxbIE3V_\lib\site-packages\flask\cli.py", line 218, in locate_app
    __import__(module_name)
  File "C:\GitHub\Ontobot\ontobot-app\flask-server\ontobot\__init__.py", line 3, in <module>
    from ontobot.services import taxonomy_service, op_service, populate_service
  File "C:\GitHub\Ontobot\ontobot-app\flask-server\ontobot\services\populate_service.py", line 76
    try
       ^
SyntaxError: expected ':'
 * Debugger is active!
 * Debugger PIN: 117-486-287
 * Detected change in 'C:\\GitHub\\Ontobot\\ontobot-app\\flask-server\\ontobot\\services\\populate_service.py', reloading
 * Restarting with stat
Traceback (most recent call last):
  File "C:\Users\Asus\.virtualenvs\flask-server-AxbIE3V_\lib\site-packages\flask\cli.py", line 897, in run_command
    app = info.load_app()
  File "C:\Users\Asus\.virtualenvs\flask-server-AxbIE3V_\lib\site-packages\flask\cli.py", line 308, in load_app
    app = locate_app(import_name, name)
  File "C:\Users\Asus\.virtualenvs\flask-server-AxbIE3V_\lib\site-packages\flask\cli.py", line 218, in locate_app
    __import__(module_name)
  File "C:\GitHub\Ontobot\ontobot-app\flask-server\ontobot\__init__.py", line 3, in <module>
    from ontobot.services import taxonomy_service, op_service, populate_service
  File "C:\GitHub\Ontobot\ontobot-app\flask-server\ontobot\services\populate_service.py", line 80
    def __is_available(obj, definedConcept):
IndentationError: expected an indented block after 'try' statement on line 76
 * Debugger is active!
 * Debugger PIN: 117-486-287
 * Detected change in 'C:\\GitHub\\Ontobot\\ontobot-app\\flask-server\\ontobot\\services\\populate_service.py', reloading
 * Restarting with stat
Traceback (most recent call last):
  File "C:\Users\Asus\.virtualenvs\flask-server-AxbIE3V_\lib\site-packages\flask\cli.py", line 897, in run_command
    app = info.load_app()
  File "C:\Users\Asus\.virtualenvs\flask-server-AxbIE3V_\lib\site-packages\flask\cli.py", line 308, in load_app
    app = locate_app(import_name, name)
  File "C:\Users\Asus\.virtualenvs\flask-server-AxbIE3V_\lib\site-packages\flask\cli.py", line 218, in locate_app
    __import__(module_name)
  File "C:\GitHub\Ontobot\ontobot-app\flask-server\ontobot\__init__.py", line 3, in <module>
    from ontobot.services import taxonomy_service, op_service, populate_service
  File "C:\GitHub\Ontobot\ontobot-app\flask-server\ontobot\services\populate_service.py", line 97
    def __is_available(obj, definedConcept):
SyntaxError: expected 'except' or 'finally' block
 * Debugger is active!
 * Debugger PIN: 117-486-287
 * Detected change in 'C:\\GitHub\\Ontobot\\ontobot-app\\flask-server\\ontobot\\services\\populate_service.py', reloading
 * Restarting with stat
Traceback (most recent call last):
  File "C:\Users\Asus\.virtualenvs\flask-server-AxbIE3V_\lib\site-packages\flask\cli.py", line 897, in run_command
    app = info.load_app()
  File "C:\Users\Asus\.virtualenvs\flask-server-AxbIE3V_\lib\site-packages\flask\cli.py", line 308, in load_app
    app = locate_app(import_name, name)
  File "C:\Users\Asus\.virtualenvs\flask-server-AxbIE3V_\lib\site-packages\flask\cli.py", line 218, in locate_app
    __import__(module_name)
  File "C:\GitHub\Ontobot\ontobot-app\flask-server\ontobot\__init__.py", line 3, in <module>
    from ontobot.services import taxonomy_service, op_service, populate_service
  File "C:\GitHub\Ontobot\ontobot-app\flask-server\ontobot\services\populate_service.py", line 98
    def __is_available(obj, definedConcept):
SyntaxError: expected 'except' or 'finally' block
 * Debugger is active!
 * Debugger PIN: 117-486-287
 * Detected change in 'C:\\GitHub\\Ontobot\\ontobot-app\\flask-server\\ontobot\\services\\populate_service.py', reloading
 * Restarting with stat
Traceback (most recent call last):
  File "C:\Users\Asus\.virtualenvs\flask-server-AxbIE3V_\lib\site-packages\flask\cli.py", line 897, in run_command
    app = info.load_app()
  File "C:\Users\Asus\.virtualenvs\flask-server-AxbIE3V_\lib\site-packages\flask\cli.py", line 308, in load_app
    app = locate_app(import_name, name)
  File "C:\Users\Asus\.virtualenvs\flask-server-AxbIE3V_\lib\site-packages\flask\cli.py", line 218, in locate_app
    __import__(module_name)
  File "C:\GitHub\Ontobot\ontobot-app\flask-server\ontobot\__init__.py", line 3, in <module>
    from ontobot.services import taxonomy_service, op_service, populate_service
  File "C:\GitHub\Ontobot\ontobot-app\flask-server\ontobot\services\populate_service.py", line 96
    except
          ^
SyntaxError: expected ':'
 * Debugger is active!
 * Debugger PIN: 117-486-287
 * Detected change in 'C:\\GitHub\\Ontobot\\ontobot-app\\flask-server\\ontobot\\services\\populate_service.py', reloading
 * Restarting with stat
 * Debugger is active!
 * Debugger PIN: 128-222-380
 * Detected change in 'C:\\GitHub\\Ontobot\\ontobot-app\\flask-server\\ontobot\\services\\populate_service.py', reloading
 * Restarting with stat
Traceback (most recent call last):
  File "C:\Users\Asus\.virtualenvs\flask-server-AxbIE3V_\lib\site-packages\flask\cli.py", line 897, in run_command
    app = info.load_app()
  File "C:\Users\Asus\.virtualenvs\flask-server-AxbIE3V_\lib\site-packages\flask\cli.py", line 308, in load_app
    app = locate_app(import_name, name)
  File "C:\Users\Asus\.virtualenvs\flask-server-AxbIE3V_\lib\site-packages\flask\cli.py", line 218, in locate_app
    __import__(module_name)
  File "C:\GitHub\Ontobot\ontobot-app\flask-server\ontobot\__init__.py", line 3, in <module>
    from ontobot.services import taxonomy_service, op_service, populate_service
  File "C:\GitHub\Ontobot\ontobot-app\flask-server\ontobot\services\populate_service.py", line 97
    return Error.
                 ^
SyntaxError: invalid syntax
 * Debugger is active!
 * Debugger PIN: 117-486-287
 * Detected change in 'C:\\GitHub\\Ontobot\\ontobot-app\\flask-server\\ontobot\\services\\populate_service.py', reloading
 * Restarting with stat
 * Debugger is active!
 * Debugger PIN: 128-222-380
 * Detected change in 'C:\\GitHub\\Ontobot\\ontobot-app\\flask-server\\ontobot\\services\\populate_service.py', reloading
 * Restarting with stat
 * Debugger is active!
 * Debugger PIN: 128-222-380
 * Detected change in 'C:\\GitHub\\Ontobot\\ontobot-app\\flask-server\\ontobot\\services\\populate_service.py', reloading
 * Restarting with stat
 * Debugger is active!
 * Debugger PIN: 128-222-380
 * Detected change in 'C:\\GitHub\\Ontobot\\ontobot-app\\flask-server\\ontobot\\services\\populate_service.py', reloading
 * Restarting with stat
 * Debugger is active!
 * Debugger PIN: 128-222-380
 * Detected change in 'C:\\GitHub\\Ontobot\\ontobot-app\\flask-server\\ontobot\\services\\populate_service.py', reloading
 * Restarting with stat
 * Debugger is active!
 * Debugger PIN: 128-222-380
127.0.0.1 - - [15/Mar/2023 10:14:26] "POST /op/checkpoint_2/populate HTTP/1.1" 500 -
Traceback (most recent call last):
  File "C:\Users\Asus\.virtualenvs\flask-server-AxbIE3V_\lib\site-packages\flask\app.py", line 2551, in __call__
    return self.wsgi_app(environ, start_response)
  File "C:\Users\Asus\.virtualenvs\flask-server-AxbIE3V_\lib\site-packages\flask\app.py", line 2531, in wsgi_app
    response = self.handle_exception(e)
  File "C:\Users\Asus\.virtualenvs\flask-server-AxbIE3V_\lib\site-packages\flask\app.py", line 2528, in wsgi_app
    response = self.full_dispatch_request()
  File "C:\Users\Asus\.virtualenvs\flask-server-AxbIE3V_\lib\site-packages\flask\app.py", line 1825, in full_dispatch_request
    rv = self.handle_user_exception(e)
  File "C:\Users\Asus\.virtualenvs\flask-server-AxbIE3V_\lib\site-packages\flask\app.py", line 1823, in full_dispatch_request
    rv = self.dispatch_request()
  File "C:\Users\Asus\.virtualenvs\flask-server-AxbIE3V_\lib\site-packages\flask\app.py", line 1799, in dispatch_request
    return self.ensure_sync(self.view_functions[rule.endpoint])(**view_args)
  File "C:\GitHub\Ontobot\ontobot-app\flask-server\ontobot\__init__.py", line 38, in add_populate
    return populate_service.convert_excel_file()
  File "C:\GitHub\Ontobot\ontobot-app\flask-server\ontobot\services\populate_service.py", line 71, in convert_excel_file
    df = pd.read_excel('../../4961e33b-29d3-47ad-89a2-34d04dfff39babc.xlsx', sheet_name=None)
  File "C:\Users\Asus\.virtualenvs\flask-server-AxbIE3V_\lib\site-packages\pandas\util\_decorators.py", line 211, in wrapper
    return func(*args, **kwargs)
  File "C:\Users\Asus\.virtualenvs\flask-server-AxbIE3V_\lib\site-packages\pandas\util\_decorators.py", line 331, in wrapper
    return func(*args, **kwargs)
  File "C:\Users\Asus\.virtualenvs\flask-server-AxbIE3V_\lib\site-packages\pandas\io\excel\_base.py", line 482, in read_excel
    io = ExcelFile(io, storage_options=storage_options, engine=engine)
  File "C:\Users\Asus\.virtualenvs\flask-server-AxbIE3V_\lib\site-packages\pandas\io\excel\_base.py", line 1652, in __init__
    ext = inspect_excel_format(
  File "C:\Users\Asus\.virtualenvs\flask-server-AxbIE3V_\lib\site-packages\pandas\io\excel\_base.py", line 1525, in inspect_excel_format
    with get_handle(
  File "C:\Users\Asus\.virtualenvs\flask-server-AxbIE3V_\lib\site-packages\pandas\io\common.py", line 865, in get_handle
    handle = open(handle, ioargs.mode)
FileNotFoundError: [Errno 2] No such file or directory: '../../4961e33b-29d3-47ad-89a2-34d04dfff39babc.xlsx'
 * Detected change in 'C:\\GitHub\\Ontobot\\ontobot-app\\flask-server\\ontobot\\services\\populate_service.py', reloading
 * Restarting with stat
 * Debugger is active!
 * Debugger PIN: 128-222-380
127.0.0.1 - - [15/Mar/2023 10:15:17] "POST /op/checkpoint_2/populate HTTP/1.1" 500 -
Traceback (most recent call last):
  File "C:\Users\Asus\.virtualenvs\flask-server-AxbIE3V_\lib\site-packages\pandas\compat\_optional.py", line 141, in import_optional_dependency
    module = importlib.import_module(name)
  File "C:\Users\Asus\AppData\Local\Programs\Python\Python310\lib\importlib\__init__.py", line 126, in import_module
    return _bootstrap._gcd_import(name[level:], package, level)
  File "<frozen importlib._bootstrap>", line 1050, in _gcd_import
  File "<frozen importlib._bootstrap>", line 1027, in _find_and_load
  File "<frozen importlib._bootstrap>", line 1004, in _find_and_load_unlocked
ModuleNotFoundError: No module named 'openpyxl'

During handling of the above exception, another exception occurred:

Traceback (most recent call last):
  File "C:\Users\Asus\.virtualenvs\flask-server-AxbIE3V_\lib\site-packages\flask\app.py", line 2551, in __call__
    return self.wsgi_app(environ, start_response)
  File "C:\Users\Asus\.virtualenvs\flask-server-AxbIE3V_\lib\site-packages\flask\app.py", line 2531, in wsgi_app
    response = self.handle_exception(e)
  File "C:\Users\Asus\.virtualenvs\flask-server-AxbIE3V_\lib\site-packages\flask\app.py", line 2528, in wsgi_app
    response = self.full_dispatch_request()
  File "C:\Users\Asus\.virtualenvs\flask-server-AxbIE3V_\lib\site-packages\flask\app.py", line 1825, in full_dispatch_request
    rv = self.handle_user_exception(e)
  File "C:\Users\Asus\.virtualenvs\flask-server-AxbIE3V_\lib\site-packages\flask\app.py", line 1823, in full_dispatch_request
    rv = self.dispatch_request()
  File "C:\Users\Asus\.virtualenvs\flask-server-AxbIE3V_\lib\site-packages\flask\app.py", line 1799, in dispatch_request
    return self.ensure_sync(self.view_functions[rule.endpoint])(**view_args)
  File "C:\GitHub\Ontobot\ontobot-app\flask-server\ontobot\__init__.py", line 38, in add_populate
    return populate_service.convert_excel_file()
  File "C:\GitHub\Ontobot\ontobot-app\flask-server\ontobot\services\populate_service.py", line 71, in convert_excel_file
    df = pd.read_excel('./4961e33b-29d3-47ad-89a2-34d04dfff39babc.xlsx', sheet_name=None)
  File "C:\Users\Asus\.virtualenvs\flask-server-AxbIE3V_\lib\site-packages\pandas\util\_decorators.py", line 211, in wrapper
    return func(*args, **kwargs)
  File "C:\Users\Asus\.virtualenvs\flask-server-AxbIE3V_\lib\site-packages\pandas\util\_decorators.py", line 331, in wrapper
    return func(*args, **kwargs)
  File "C:\Users\Asus\.virtualenvs\flask-server-AxbIE3V_\lib\site-packages\pandas\io\excel\_base.py", line 482, in read_excel
    io = ExcelFile(io, storage_options=storage_options, engine=engine)
  File "C:\Users\Asus\.virtualenvs\flask-server-AxbIE3V_\lib\site-packages\pandas\io\excel\_base.py", line 1695, in __init__
    self._reader = self._engines[engine](self._io, storage_options=storage_options)
  File "C:\Users\Asus\.virtualenvs\flask-server-AxbIE3V_\lib\site-packages\pandas\io\excel\_openpyxl.py", line 556, in __init__
    import_optional_dependency("openpyxl")
  File "C:\Users\Asus\.virtualenvs\flask-server-AxbIE3V_\lib\site-packages\pandas\compat\_optional.py", line 144, in import_optional_dependency
    raise ImportError(msg)
ImportError: Missing optional dependency 'openpyxl'.  Use pip or conda to install openpyxl.
 * Detected change in 'C:\\GitHub\\Ontobot\\ontobot-app\\flask-server\\ontobot\\services\\populate_service.py', reloading
 * Restarting with stat
 * Debugger is active!
 * Debugger PIN: 128-222-380
127.0.0.1 - - [15/Mar/2023 10:16:48] "POST /op/checkpoint_2/populate HTTP/1.1" 500 -
Traceback (most recent call last):
  File "C:\Users\Asus\.virtualenvs\flask-server-AxbIE3V_\lib\site-packages\pandas\compat\_optional.py", line 141, in import_optional_dependency
    module = importlib.import_module(name)
  File "C:\Users\Asus\AppData\Local\Programs\Python\Python310\lib\importlib\__init__.py", line 126, in import_module
    return _bootstrap._gcd_import(name[level:], package, level)
  File "<frozen importlib._bootstrap>", line 1050, in _gcd_import
  File "<frozen importlib._bootstrap>", line 1027, in _find_and_load
  File "<frozen importlib._bootstrap>", line 1004, in _find_and_load_unlocked
ModuleNotFoundError: No module named 'openpyxl'

During handling of the above exception, another exception occurred:

Traceback (most recent call last):
  File "C:\Users\Asus\.virtualenvs\flask-server-AxbIE3V_\lib\site-packages\flask\app.py", line 2551, in __call__
    return self.wsgi_app(environ, start_response)
  File "C:\Users\Asus\.virtualenvs\flask-server-AxbIE3V_\lib\site-packages\flask\app.py", line 2531, in wsgi_app
    response = self.handle_exception(e)
  File "C:\Users\Asus\.virtualenvs\flask-server-AxbIE3V_\lib\site-packages\flask\app.py", line 2528, in wsgi_app
    response = self.full_dispatch_request()
  File "C:\Users\Asus\.virtualenvs\flask-server-AxbIE3V_\lib\site-packages\flask\app.py", line 1825, in full_dispatch_request
    rv = self.handle_user_exception(e)
  File "C:\Users\Asus\.virtualenvs\flask-server-AxbIE3V_\lib\site-packages\flask\app.py", line 1823, in full_dispatch_request
    rv = self.dispatch_request()
  File "C:\Users\Asus\.virtualenvs\flask-server-AxbIE3V_\lib\site-packages\flask\app.py", line 1799, in dispatch_request
    return self.ensure_sync(self.view_functions[rule.endpoint])(**view_args)
  File "C:\GitHub\Ontobot\ontobot-app\flask-server\ontobot\__init__.py", line 38, in add_populate
    return populate_service.convert_excel_file()
  File "C:\GitHub\Ontobot\ontobot-app\flask-server\ontobot\services\populate_service.py", line 71, in convert_excel_file
    df = pd.read_excel('4961e33b-29d3-47ad-89a2-34d04dfff39babc.xlsx', sheet_name=None)
  File "C:\Users\Asus\.virtualenvs\flask-server-AxbIE3V_\lib\site-packages\pandas\util\_decorators.py", line 211, in wrapper
    return func(*args, **kwargs)
  File "C:\Users\Asus\.virtualenvs\flask-server-AxbIE3V_\lib\site-packages\pandas\util\_decorators.py", line 331, in wrapper
    return func(*args, **kwargs)
  File "C:\Users\Asus\.virtualenvs\flask-server-AxbIE3V_\lib\site-packages\pandas\io\excel\_base.py", line 482, in read_excel
    io = ExcelFile(io, storage_options=storage_options, engine=engine)
  File "C:\Users\Asus\.virtualenvs\flask-server-AxbIE3V_\lib\site-packages\pandas\io\excel\_base.py", line 1695, in __init__
    self._reader = self._engines[engine](self._io, storage_options=storage_options)
  File "C:\Users\Asus\.virtualenvs\flask-server-AxbIE3V_\lib\site-packages\pandas\io\excel\_openpyxl.py", line 556, in __init__
    import_optional_dependency("openpyxl")
  File "C:\Users\Asus\.virtualenvs\flask-server-AxbIE3V_\lib\site-packages\pandas\compat\_optional.py", line 144, in import_optional_dependency
    raise ImportError(msg)
ImportError: Missing optional dependency 'openpyxl'.  Use pip or conda to install openpyxl.
127.0.0.1 - - [15/Mar/2023 10:16:49] "POST /op/checkpoint_2/populate HTTP/1.1" 500 -
Traceback (most recent call last):
  File "C:\Users\Asus\.virtualenvs\flask-server-AxbIE3V_\lib\site-packages\pandas\compat\_optional.py", line 141, in import_optional_dependency
    module = importlib.import_module(name)
  File "C:\Users\Asus\AppData\Local\Programs\Python\Python310\lib\importlib\__init__.py", line 126, in import_module
    return _bootstrap._gcd_import(name[level:], package, level)
  File "<frozen importlib._bootstrap>", line 1050, in _gcd_import
  File "<frozen importlib._bootstrap>", line 1027, in _find_and_load
  File "<frozen importlib._bootstrap>", line 1004, in _find_and_load_unlocked
ModuleNotFoundError: No module named 'openpyxl'

During handling of the above exception, another exception occurred:

Traceback (most recent call last):
  File "C:\Users\Asus\.virtualenvs\flask-server-AxbIE3V_\lib\site-packages\flask\app.py", line 2551, in __call__
    return self.wsgi_app(environ, start_response)
  File "C:\Users\Asus\.virtualenvs\flask-server-AxbIE3V_\lib\site-packages\flask\app.py", line 2531, in wsgi_app
    response = self.handle_exception(e)
  File "C:\Users\Asus\.virtualenvs\flask-server-AxbIE3V_\lib\site-packages\flask\app.py", line 2528, in wsgi_app
    response = self.full_dispatch_request()
  File "C:\Users\Asus\.virtualenvs\flask-server-AxbIE3V_\lib\site-packages\flask\app.py", line 1825, in full_dispatch_request
    rv = self.handle_user_exception(e)
  File "C:\Users\Asus\.virtualenvs\flask-server-AxbIE3V_\lib\site-packages\flask\app.py", line 1823, in full_dispatch_request
    rv = self.dispatch_request()
  File "C:\Users\Asus\.virtualenvs\flask-server-AxbIE3V_\lib\site-packages\flask\app.py", line 1799, in dispatch_request
    return self.ensure_sync(self.view_functions[rule.endpoint])(**view_args)
  File "C:\GitHub\Ontobot\ontobot-app\flask-server\ontobot\__init__.py", line 38, in add_populate
    return populate_service.convert_excel_file()
  File "C:\GitHub\Ontobot\ontobot-app\flask-server\ontobot\services\populate_service.py", line 71, in convert_excel_file
    df = pd.read_excel('4961e33b-29d3-47ad-89a2-34d04dfff39babc.xlsx', sheet_name=None)
  File "C:\Users\Asus\.virtualenvs\flask-server-AxbIE3V_\lib\site-packages\pandas\util\_decorators.py", line 211, in wrapper
    return func(*args, **kwargs)
  File "C:\Users\Asus\.virtualenvs\flask-server-AxbIE3V_\lib\site-packages\pandas\util\_decorators.py", line 331, in wrapper
    return func(*args, **kwargs)
  File "C:\Users\Asus\.virtualenvs\flask-server-AxbIE3V_\lib\site-packages\pandas\io\excel\_base.py", line 482, in read_excel
    io = ExcelFile(io, storage_options=storage_options, engine=engine)
  File "C:\Users\Asus\.virtualenvs\flask-server-AxbIE3V_\lib\site-packages\pandas\io\excel\_base.py", line 1695, in __init__
    self._reader = self._engines[engine](self._io, storage_options=storage_options)
  File "C:\Users\Asus\.virtualenvs\flask-server-AxbIE3V_\lib\site-packages\pandas\io\excel\_openpyxl.py", line 556, in __init__
    import_optional_dependency("openpyxl")
  File "C:\Users\Asus\.virtualenvs\flask-server-AxbIE3V_\lib\site-packages\pandas\compat\_optional.py", line 144, in import_optional_dependency
    raise ImportError(msg)
ImportError: Missing optional dependency 'openpyxl'.  Use pip or conda to install openpyxl.
127.0.0.1 - - [15/Mar/2023 10:17:36] "POST /op/checkpoint_2/populate HTTP/1.1" 200 -
 * Detected change in 'C:\\GitHub\\Ontobot\\ontobot-app\\flask-server\\ontobot\\services\\populate_service.py', reloading
 * Restarting with stat
Traceback (most recent call last):
  File "C:\Users\Asus\.virtualenvs\flask-server-AxbIE3V_\lib\site-packages\flask\cli.py", line 897, in run_command
    app = info.load_app()
  File "C:\Users\Asus\.virtualenvs\flask-server-AxbIE3V_\lib\site-packages\flask\cli.py", line 308, in load_app
    app = locate_app(import_name, name)
  File "C:\Users\Asus\.virtualenvs\flask-server-AxbIE3V_\lib\site-packages\flask\cli.py", line 218, in locate_app
    __import__(module_name)
  File "C:\GitHub\Ontobot\ontobot-app\flask-server\ontobot\__init__.py", line 3, in <module>
    from ontobot.services import taxonomy_service, op_service, populate_service
  File "C:\GitHub\Ontobot\ontobot-app\flask-server\ontobot\services\populate_service.py", line 88
    row_data[column_name.] = row[column_name]
                         ^
SyntaxError: invalid syntax
 * Debugger is active!
 * Debugger PIN: 117-486-287
 * Detected change in 'C:\\GitHub\\Ontobot\\ontobot-app\\flask-server\\ontobot\\services\\populate_service.py', reloading
 * Restarting with stat
 * Debugger is active!
 * Debugger PIN: 128-222-380
 * Detected change in 'C:\\GitHub\\Ontobot\\ontobot-app\\flask-server\\ontobot\\services\\populate_service.py', reloading
 * Restarting with stat
 * Debugger is active!
 * Debugger PIN: 128-222-380
 * Detected change in 'C:\\GitHub\\Ontobot\\ontobot-app\\flask-server\\ontobot\\services\\populate_service.py', reloading
 * Restarting with stat
Traceback (most recent call last):
  File "C:\Users\Asus\.virtualenvs\flask-server-AxbIE3V_\lib\site-packages\flask\cli.py", line 897, in run_command
    app = info.load_app()
  File "C:\Users\Asus\.virtualenvs\flask-server-AxbIE3V_\lib\site-packages\flask\cli.py", line 308, in load_app
    app = locate_app(import_name, name)
  File "C:\Users\Asus\.virtualenvs\flask-server-AxbIE3V_\lib\site-packages\flask\cli.py", line 218, in locate_app
    __import__(module_name)
  File "C:\GitHub\Ontobot\ontobot-app\flask-server\ontobot\__init__.py", line 3, in <module>
    from ontobot.services import taxonomy_service, op_service, populate_service
  File "C:\GitHub\Ontobot\ontobot-app\flask-server\ontobot\services\populate_service.py", line 86
    for column_name:s in df[sheet_name].columns:
                   ^
SyntaxError: invalid syntax
 * Debugger is active!
 * Debugger PIN: 117-486-287
 * Detected change in 'C:\\GitHub\\Ontobot\\ontobot-app\\flask-server\\ontobot\\services\\populate_service.py', reloading
 * Restarting with stat
Traceback (most recent call last):
  File "C:\Users\Asus\.virtualenvs\flask-server-AxbIE3V_\lib\site-packages\flask\cli.py", line 897, in run_command
    app = info.load_app()
  File "C:\Users\Asus\.virtualenvs\flask-server-AxbIE3V_\lib\site-packages\flask\cli.py", line 308, in load_app
    app = locate_app(import_name, name)
  File "C:\Users\Asus\.virtualenvs\flask-server-AxbIE3V_\lib\site-packages\flask\cli.py", line 218, in locate_app
    __import__(module_name)
  File "C:\GitHub\Ontobot\ontobot-app\flask-server\ontobot\__init__.py", line 3, in <module>
    from ontobot.services import taxonomy_service, op_service, populate_service
  File "C:\GitHub\Ontobot\ontobot-app\flask-server\ontobot\services\populate_service.py", line 86
    for column_name:str in df[sheet_name].columns:
                   ^
SyntaxError: invalid syntax
 * Debugger is active!
 * Debugger PIN: 117-486-287
 * Detected change in 'C:\\GitHub\\Ontobot\\ontobot-app\\flask-server\\ontobot\\services\\populate_service.py', reloading
 * Restarting with stat
 * Debugger is active!
 * Debugger PIN: 128-222-380
 * Detected change in 'C:\\GitHub\\Ontobot\\ontobot-app\\flask-server\\ontobot\\services\\populate_service.py', reloading
 * Restarting with stat
 * Debugger is active!
 * Debugger PIN: 128-222-380
 * Detected change in 'C:\\GitHub\\Ontobot\\ontobot-app\\flask-server\\ontobot\\services\\populate_service.py', reloading
 * Restarting with stat
 * Debugger is active!
 * Debugger PIN: 128-222-380
 * Detected change in 'C:\\GitHub\\Ontobot\\ontobot-app\\flask-server\\ontobot\\services\\populate_service.py', reloading
 * Restarting with stat
 * Debugger is active!
 * Debugger PIN: 128-222-380
 * Detected change in 'C:\\GitHub\\Ontobot\\ontobot-app\\flask-server\\ontobot\\services\\populate_service.py', reloading
 * Restarting with stat
 * Debugger is active!
 * Debugger PIN: 128-222-380
127.0.0.1 - - [15/Mar/2023 10:21:48] "POST /op/checkpoint_2/populate HTTP/1.1" 200 -
127.0.0.1 - - [15/Mar/2023 10:49:15] "POST /op/checkpoint_2/populate HTTP/1.1" 200 -
 * Detected change in 'C:\\GitHub\\Ontobot\\ontobot-app\\flask-server\\ontobot\\services\\populate_service.py', reloading
 * Restarting with stat
 * Debugger is active!
 * Debugger PIN: 128-222-380
 * Detected change in 'C:\\GitHub\\Ontobot\\ontobot-app\\flask-server\\ontobot\\services\\populate_service.py', reloading
 * Restarting with stat
Traceback (most recent call last):
  File "C:\Users\Asus\.virtualenvs\flask-server-AxbIE3V_\lib\site-packages\flask\cli.py", line 897, in run_command
    app = info.load_app()
  File "C:\Users\Asus\.virtualenvs\flask-server-AxbIE3V_\lib\site-packages\flask\cli.py", line 308, in load_app
    app = locate_app(import_name, name)
  File "C:\Users\Asus\.virtualenvs\flask-server-AxbIE3V_\lib\site-packages\flask\cli.py", line 218, in locate_app
    __import__(module_name)
  File "C:\GitHub\Ontobot\ontobot-app\flask-server\ontobot\__init__.py", line 3, in <module>
    from ontobot.services import taxonomy_service, op_service, populate_service
  File "C:\GitHub\Ontobot\ontobot-app\flask-server\ontobot\services\populate_service.py", line 88
    if 
       ^
SyntaxError: invalid syntax
 * Debugger is active!
 * Debugger PIN: 117-486-287
 * Detected change in 'C:\\GitHub\\Ontobot\\ontobot-app\\flask-server\\ontobot\\services\\populate_service.py', reloading
 * Restarting with stat
Traceback (most recent call last):
  File "C:\Users\Asus\.virtualenvs\flask-server-AxbIE3V_\lib\site-packages\flask\cli.py", line 897, in run_command
    app = info.load_app()
  File "C:\Users\Asus\.virtualenvs\flask-server-AxbIE3V_\lib\site-packages\flask\cli.py", line 308, in load_app
    app = locate_app(import_name, name)
  File "C:\Users\Asus\.virtualenvs\flask-server-AxbIE3V_\lib\site-packages\flask\cli.py", line 218, in locate_app
    __import__(module_name)
  File "C:\GitHub\Ontobot\ontobot-app\flask-server\ontobot\__init__.py", line 3, in <module>
    from ontobot.services import taxonomy_service, op_service, populate_service
  File "C:\GitHub\Ontobot\ontobot-app\flask-server\ontobot\services\populate_service.py", line 88
    if ro
         ^
SyntaxError: expected ':'
 * Debugger is active!
 * Debugger PIN: 117-486-287
 * Detected change in 'C:\\GitHub\\Ontobot\\ontobot-app\\flask-server\\ontobot\\services\\populate_service.py', reloading
 * Restarting with stat
Traceback (most recent call last):
  File "C:\Users\Asus\.virtualenvs\flask-server-AxbIE3V_\lib\site-packages\flask\cli.py", line 897, in run_command
    app = info.load_app()
  File "C:\Users\Asus\.virtualenvs\flask-server-AxbIE3V_\lib\site-packages\flask\cli.py", line 308, in load_app
    app = locate_app(import_name, name)
  File "C:\Users\Asus\.virtualenvs\flask-server-AxbIE3V_\lib\site-packages\flask\cli.py", line 218, in locate_app
    __import__(module_name)
  File "C:\GitHub\Ontobot\ontobot-app\flask-server\ontobot\__init__.py", line 3, in <module>
    from ontobot.services import taxonomy_service, op_service, populate_service
  File "C:\GitHub\Ontobot\ontobot-app\flask-server\ontobot\services\populate_service.py", line 88
    if row
          ^
SyntaxError: expected ':'
 * Debugger is active!
 * Debugger PIN: 117-486-287
 * Detected change in 'C:\\GitHub\\Ontobot\\ontobot-app\\flask-server\\ontobot\\services\\populate_service.py', reloading
 * Restarting with stat
Traceback (most recent call last):
  File "C:\Users\Asus\.virtualenvs\flask-server-AxbIE3V_\lib\site-packages\flask\cli.py", line 897, in run_command
    app = info.load_app()
  File "C:\Users\Asus\.virtualenvs\flask-server-AxbIE3V_\lib\site-packages\flask\cli.py", line 308, in load_app
    app = locate_app(import_name, name)
  File "C:\Users\Asus\.virtualenvs\flask-server-AxbIE3V_\lib\site-packages\flask\cli.py", line 218, in locate_app
    __import__(module_name)
  File "C:\GitHub\Ontobot\ontobot-app\flask-server\ontobot\__init__.py", line 3, in <module>
    from ontobot.services import taxonomy_service, op_service, populate_service
  File "C:\GitHub\Ontobot\ontobot-app\flask-server\ontobot\services\populate_service.py", line 88
    if row[column_name]
                       ^
SyntaxError: expected ':'
 * Debugger is active!
 * Debugger PIN: 117-486-287
 * Detected change in 'C:\\GitHub\\Ontobot\\ontobot-app\\flask-server\\ontobot\\services\\populate_service.py', reloading
 * Restarting with stat
Traceback (most recent call last):
  File "C:\Users\Asus\.virtualenvs\flask-server-AxbIE3V_\lib\site-packages\flask\cli.py", line 897, in run_command
    app = info.load_app()
  File "C:\Users\Asus\.virtualenvs\flask-server-AxbIE3V_\lib\site-packages\flask\cli.py", line 308, in load_app
    app = locate_app(import_name, name)
  File "C:\Users\Asus\.virtualenvs\flask-server-AxbIE3V_\lib\site-packages\flask\cli.py", line 218, in locate_app
    __import__(module_name)
  File "C:\GitHub\Ontobot\ontobot-app\flask-server\ontobot\__init__.py", line 3, in <module>
    from ontobot.services import taxonomy_service, op_service, populate_service
  File "C:\GitHub\Ontobot\ontobot-app\flask-server\ontobot\services\populate_service.py", line 89
    row_data[column_name.split("(")[0].strip()] = row[column_name]
    ^^^^^^^^
IndentationError: expected an indented block after 'if' statement on line 88
 * Debugger is active!
 * Debugger PIN: 117-486-287
 * Detected change in 'C:\\GitHub\\Ontobot\\ontobot-app\\flask-server\\ontobot\\services\\populate_service.py', reloading
 * Restarting with stat
 * Debugger is active!
 * Debugger PIN: 128-222-380
 * Detected change in 'C:\\GitHub\\Ontobot\\ontobot-app\\flask-server\\ontobot\\services\\populate_service.py', reloading
 * Restarting with stat
Traceback (most recent call last):
  File "C:\Users\Asus\.virtualenvs\flask-server-AxbIE3V_\lib\site-packages\flask\cli.py", line 897, in run_command
    app = info.load_app()
  File "C:\Users\Asus\.virtualenvs\flask-server-AxbIE3V_\lib\site-packages\flask\cli.py", line 308, in load_app
    app = locate_app(import_name, name)
  File "C:\Users\Asus\.virtualenvs\flask-server-AxbIE3V_\lib\site-packages\flask\cli.py", line 218, in locate_app
    __import__(module_name)
  File "C:\GitHub\Ontobot\ontobot-app\flask-server\ontobot\__init__.py", line 3, in <module>
    from ontobot.services import taxonomy_service, op_service, populate_service
  File "C:\GitHub\Ontobot\ontobot-app\flask-server\ontobot\services\populate_service.py", line 93
    data.append(row_data)
IndentationError: expected an indented block after 'else' statement on line 90
 * Debugger is active!
 * Debugger PIN: 117-486-287
 * Detected change in 'C:\\GitHub\\Ontobot\\ontobot-app\\flask-server\\ontobot\\services\\populate_service.py', reloading
 * Restarting with stat
 * Debugger is active!
 * Debugger PIN: 128-222-380
 * Detected change in 'C:\\GitHub\\Ontobot\\ontobot-app\\flask-server\\ontobot\\services\\populate_service.py', reloading
 * Restarting with stat
 * Debugger is active!
 * Debugger PIN: 128-222-380
127.0.0.1 - - [15/Mar/2023 10:51:16] "POST /op/checkpoint_2/populate HTTP/1.1" 200 -
127.0.0.1 - - [15/Mar/2023 10:51:37] "POST /op/checkpoint_2/populate HTTP/1.1" 200 -
 * Detected change in 'C:\\GitHub\\Ontobot\\ontobot-app\\flask-server\\ontobot\\services\\populate_service.py', reloading
 * Restarting with stat
 * Debugger is active!
 * Debugger PIN: 128-222-380
127.0.0.1 - - [15/Mar/2023 10:51:53] "POST /op/checkpoint_2/populate HTTP/1.1" 200 -
 * Detected change in 'C:\\GitHub\\Ontobot\\ontobot-app\\flask-server\\ontobot\\services\\populate_service.py', reloading
 * Restarting with stat
 * Debugger is active!
 * Debugger PIN: 128-222-380
 * Detected change in 'C:\\GitHub\\Ontobot\\ontobot-app\\flask-server\\ontobot\\services\\populate_service.py', reloading
 * Restarting with stat
 * Debugger is active!
 * Debugger PIN: 128-222-380
 * Detected change in 'C:\\GitHub\\Ontobot\\ontobot-app\\flask-server\\ontobot\\services\\populate_service.py', reloading
 * Restarting with stat
 * Debugger is active!
 * Debugger PIN: 128-222-380
 * Detected change in 'C:\\GitHub\\Ontobot\\ontobot-app\\flask-server\\ontobot\\services\\populate_service.py', reloading
 * Restarting with stat
 * Debugger is active!
 * Debugger PIN: 128-222-380
 * Detected change in 'C:\\GitHub\\Ontobot\\ontobot-app\\flask-server\\ontobot\\services\\populate_service.py', reloading
 * Restarting with stat
 * Debugger is active!
 * Debugger PIN: 128-222-380
127.0.0.1 - - [15/Mar/2023 10:52:28] "POST /op/checkpoint_2/populate HTTP/1.1" 200 -
 * Detected change in 'C:\\GitHub\\Ontobot\\ontobot-app\\flask-server\\ontobot\\services\\populate_service.py', reloading
 * Restarting with stat
 * Debugger is active!
 * Debugger PIN: 128-222-380
127.0.0.1 - - [15/Mar/2023 10:54:03] "POST /op/checkpoint_2/populate HTTP/1.1" 200 -
 * Detected change in 'C:\\GitHub\\Ontobot\\ontobot-app\\flask-server\\ontobot\\services\\populate_service.py', reloading
 * Restarting with stat
Traceback (most recent call last):
  File "C:\Users\Asus\.virtualenvs\flask-server-AxbIE3V_\lib\site-packages\flask\cli.py", line 897, in run_command
    app = info.load_app()
  File "C:\Users\Asus\.virtualenvs\flask-server-AxbIE3V_\lib\site-packages\flask\cli.py", line 308, in load_app
    app = locate_app(import_name, name)
  File "C:\Users\Asus\.virtualenvs\flask-server-AxbIE3V_\lib\site-packages\flask\cli.py", line 223, in locate_app
    raise NoAppException(
flask.cli.NoAppException: While importing 'ontobot', an ImportError was raised:

Traceback (most recent call last):
  File "C:\Users\Asus\.virtualenvs\flask-server-AxbIE3V_\lib\site-packages\flask\cli.py", line 218, in locate_app
    __import__(module_name)
  File "C:\GitHub\Ontobot\ontobot-app\flask-server\ontobot\__init__.py", line 3, in <module>
    from ontobot.services import taxonomy_service, op_service, populate_service
  File "C:\GitHub\Ontobot\ontobot-app\flask-server\ontobot\services\populate_service.py", line 1, in <module>
    import xlsxwriter, ma
ModuleNotFoundError: No module named 'ma'

 * Debugger is active!
 * Debugger PIN: 117-486-287
 * Detected change in 'C:\\GitHub\\Ontobot\\ontobot-app\\flask-server\\ontobot\\services\\populate_service.py', reloading
 * Restarting with stat
 * Debugger is active!
 * Debugger PIN: 128-222-380
